[2025-02-19T06:57:28.465+0000] {taskinstance.py:1125} INFO - Dependencies all met for dep_context=non-requeueable deps ti=<TaskInstance: api_to_snowflake.load_data_to_snowflake scheduled__2025-02-18T06:51:51.509301+00:00 [queued]>
[2025-02-19T06:57:28.491+0000] {taskinstance.py:1125} INFO - Dependencies all met for dep_context=requeueable deps ti=<TaskInstance: api_to_snowflake.load_data_to_snowflake scheduled__2025-02-18T06:51:51.509301+00:00 [queued]>
[2025-02-19T06:57:28.493+0000] {taskinstance.py:1331} INFO - Starting attempt 2 of 2
[2025-02-19T06:57:28.535+0000] {taskinstance.py:1350} INFO - Executing <Task(PythonOperator): load_data_to_snowflake> on 2025-02-18 06:51:51.509301+00:00
[2025-02-19T06:57:28.549+0000] {standard_task_runner.py:57} INFO - Started process 254 to run task
[2025-02-19T06:57:28.556+0000] {standard_task_runner.py:84} INFO - Running: ['***', 'tasks', 'run', 'api_to_snowflake', 'load_data_to_snowflake', 'scheduled__2025-02-18T06:51:51.509301+00:00', '--job-id', '10', '--raw', '--subdir', 'DAGS_FOLDER/api_to_snowflake.py', '--cfg-path', '/tmp/tmp_jux1b2b']
[2025-02-19T06:57:28.559+0000] {standard_task_runner.py:85} INFO - Job 10: Subtask load_data_to_snowflake
[2025-02-19T06:57:28.655+0000] {task_command.py:410} INFO - Running <TaskInstance: api_to_snowflake.load_data_to_snowflake scheduled__2025-02-18T06:51:51.509301+00:00 [running]> on host a5ad21395fb4
[2025-02-19T06:57:28.753+0000] {taskinstance.py:1570} INFO - Exporting env vars: AIRFLOW_CTX_DAG_EMAIL='your-email@example.com' AIRFLOW_CTX_DAG_OWNER='***' AIRFLOW_CTX_DAG_ID='api_to_snowflake' AIRFLOW_CTX_TASK_ID='load_data_to_snowflake' AIRFLOW_CTX_EXECUTION_DATE='2025-02-18T06:51:51.509301+00:00' AIRFLOW_CTX_TRY_NUMBER='2' AIRFLOW_CTX_DAG_RUN_ID='scheduled__2025-02-18T06:51:51.509301+00:00'
[2025-02-19T06:57:28.768+0000] {connection.py:287} INFO - Snowflake Connector for Python Version: 3.0.3, Python Version: 3.7.16, Platform: Linux-6.10.11-linuxkit-x86_64-with-debian-11.7
[2025-02-19T06:57:28.769+0000] {connection.py:990} INFO - This connection is in OCSP Fail Open Mode. TLS Certificates would be checked for validity and revocation status. Any other Certificate Revocation related exceptions or OCSP Responder failures would be disregarded in favor of connectivity.
[2025-02-19T06:57:28.769+0000] {connection.py:1007} INFO - Setting use_openssl_only mode to False
[2025-02-19T06:57:30.207+0000] {cursor.py:800} INFO - query: [INSERT INTO your_table (region, region_code, period, atleast_one_measure, immuni...]
[2025-02-19T06:57:30.529+0000] {cursor.py:813} INFO - query execution done
[2025-02-19T06:57:30.533+0000] {connection.py:586} INFO - closed
[2025-02-19T06:57:30.845+0000] {connection.py:589} INFO - No async queries seem to be running, deleting session
[2025-02-19T06:57:31.155+0000] {taskinstance.py:1847} ERROR - Task failed with exception
Traceback (most recent call last):
  File "/home/airflow/.local/lib/python3.7/site-packages/airflow/operators/python.py", line 181, in execute
    return_value = self.execute_callable()
  File "/home/airflow/.local/lib/python3.7/site-packages/airflow/operators/python.py", line 198, in execute_callable
    return self.python_callable(*self.op_args, **self.op_kwargs)
  File "/opt/airflow/dags/api_to_snowflake.py", line 57, in load_data_to_snowflake
    cs.execute(query)
  File "/home/airflow/.local/lib/python3.7/site-packages/snowflake/connector/cursor.py", line 904, in execute
    Error.errorhandler_wrapper(self.connection, self, error_class, errvalue)
  File "/home/airflow/.local/lib/python3.7/site-packages/snowflake/connector/errors.py", line 294, in errorhandler_wrapper
    error_value,
  File "/home/airflow/.local/lib/python3.7/site-packages/snowflake/connector/errors.py", line 345, in hand_to_other_handler
    cursor.errorhandler(connection, cursor, error_class, error_value)
  File "/home/airflow/.local/lib/python3.7/site-packages/snowflake/connector/errors.py", line 231, in default_errorhandler
    cursor=cursor,
snowflake.connector.errors.ProgrammingError: 002003 (42S02): 01ba7de1-0000-dfca-0008-a54a0007d00a: SQL compilation error:
Table 'YOUR_TABLE' does not exist or not authorized.
[2025-02-19T06:57:31.167+0000] {taskinstance.py:1373} INFO - Marking task as FAILED. dag_id=api_to_snowflake, task_id=load_data_to_snowflake, execution_date=20250218T065151, start_date=20250219T065728, end_date=20250219T065731
[2025-02-19T06:57:31.184+0000] {standard_task_runner.py:109} ERROR - Failed to execute job 10 for task load_data_to_snowflake (002003 (42S02): 01ba7de1-0000-dfca-0008-a54a0007d00a: SQL compilation error:
Table 'YOUR_TABLE' does not exist or not authorized.; 254)
[2025-02-19T06:57:31.201+0000] {local_task_job_runner.py:232} INFO - Task exited with return code 1
[2025-02-19T06:57:31.224+0000] {taskinstance.py:2674} INFO - 0 downstream tasks scheduled from follow-on schedule check
