[2025-02-19T06:38:12.211+0000] {taskinstance.py:1125} INFO - Dependencies all met for dep_context=non-requeueable deps ti=<TaskInstance: api_to_snowflake.fetch_api_data scheduled__2025-02-18T06:38:04.711509+00:00 [queued]>
[2025-02-19T06:38:12.227+0000] {taskinstance.py:1125} INFO - Dependencies all met for dep_context=requeueable deps ti=<TaskInstance: api_to_snowflake.fetch_api_data scheduled__2025-02-18T06:38:04.711509+00:00 [queued]>
[2025-02-19T06:38:12.227+0000] {taskinstance.py:1331} INFO - Starting attempt 1 of 2
[2025-02-19T06:38:12.322+0000] {taskinstance.py:1350} INFO - Executing <Task(PythonOperator): fetch_api_data> on 2025-02-18 06:38:04.711509+00:00
[2025-02-19T06:38:12.327+0000] {standard_task_runner.py:57} INFO - Started process 156 to run task
[2025-02-19T06:38:12.330+0000] {standard_task_runner.py:84} INFO - Running: ['***', 'tasks', 'run', 'api_to_snowflake', 'fetch_api_data', 'scheduled__2025-02-18T06:38:04.711509+00:00', '--job-id', '2', '--raw', '--subdir', 'DAGS_FOLDER/api_to_snowflake.py', '--cfg-path', '/tmp/tmp6w59p9oo']
[2025-02-19T06:38:12.332+0000] {standard_task_runner.py:85} INFO - Job 2: Subtask fetch_api_data
[2025-02-19T06:38:12.385+0000] {task_command.py:410} INFO - Running <TaskInstance: api_to_snowflake.fetch_api_data scheduled__2025-02-18T06:38:04.711509+00:00 [running]> on host a5ad21395fb4
[2025-02-19T06:38:12.480+0000] {taskinstance.py:1570} INFO - Exporting env vars: AIRFLOW_CTX_DAG_EMAIL='your-email@example.com' AIRFLOW_CTX_DAG_OWNER='***' AIRFLOW_CTX_DAG_ID='api_to_snowflake' AIRFLOW_CTX_TASK_ID='fetch_api_data' AIRFLOW_CTX_EXECUTION_DATE='2025-02-18T06:38:04.711509+00:00' AIRFLOW_CTX_TRY_NUMBER='1' AIRFLOW_CTX_DAG_RUN_ID='scheduled__2025-02-18T06:38:04.711509+00:00'
[2025-02-19T06:38:20.490+0000] {taskinstance.py:1847} ERROR - Task failed with exception
Traceback (most recent call last):
  File "/home/airflow/.local/lib/python3.7/site-packages/urllib3/connection.py", line 175, in _new_conn
    (self._dns_host, self.port), self.timeout, **extra_kw
  File "/home/airflow/.local/lib/python3.7/site-packages/urllib3/util/connection.py", line 72, in create_connection
    for res in socket.getaddrinfo(host, port, family, socket.SOCK_STREAM):
  File "/usr/local/lib/python3.7/socket.py", line 752, in getaddrinfo
    for res in _socket.getaddrinfo(host, port, family, type, proto, flags):
socket.gaierror: [Errno -3] Temporary failure in name resolution

During handling of the above exception, another exception occurred:

Traceback (most recent call last):
  File "/home/airflow/.local/lib/python3.7/site-packages/urllib3/connectionpool.py", line 710, in urlopen
    chunked=chunked,
  File "/home/airflow/.local/lib/python3.7/site-packages/urllib3/connectionpool.py", line 386, in _make_request
    self._validate_conn(conn)
  File "/home/airflow/.local/lib/python3.7/site-packages/urllib3/connectionpool.py", line 1042, in _validate_conn
    conn.connect()
  File "/home/airflow/.local/lib/python3.7/site-packages/urllib3/connection.py", line 363, in connect
    self.sock = conn = self._new_conn()
  File "/home/airflow/.local/lib/python3.7/site-packages/urllib3/connection.py", line 187, in _new_conn
    self, "Failed to establish a new connection: %s" % e
urllib3.exceptions.NewConnectionError: <urllib3.connection.HTTPSConnection object at 0x7fa93a27b210>: Failed to establish a new connection: [Errno -3] Temporary failure in name resolution

During handling of the above exception, another exception occurred:

Traceback (most recent call last):
  File "/home/airflow/.local/lib/python3.7/site-packages/requests/adapters.py", line 498, in send
    chunked=chunked,
  File "/home/airflow/.local/lib/python3.7/site-packages/urllib3/connectionpool.py", line 788, in urlopen
    method, url, error=e, _pool=self, _stacktrace=sys.exc_info()[2]
  File "/home/airflow/.local/lib/python3.7/site-packages/urllib3/util/retry.py", line 592, in increment
    raise MaxRetryError(_pool, url, error or ResponseError(cause))
urllib3.exceptions.MaxRetryError: HTTPSConnectionPool(host='api.example.com', port=443): Max retries exceeded with url: /data (Caused by NewConnectionError('<urllib3.connection.HTTPSConnection object at 0x7fa93a27b210>: Failed to establish a new connection: [Errno -3] Temporary failure in name resolution'))

During handling of the above exception, another exception occurred:

Traceback (most recent call last):
  File "/home/airflow/.local/lib/python3.7/site-packages/airflow/operators/python.py", line 181, in execute
    return_value = self.execute_callable()
  File "/home/airflow/.local/lib/python3.7/site-packages/airflow/operators/python.py", line 198, in execute_callable
    return self.python_callable(*self.op_args, **self.op_kwargs)
  File "/opt/airflow/dags/api_to_snowflake.py", line 16, in fetch_api_data
    response = requests.get(api_url)
  File "/home/airflow/.local/lib/python3.7/site-packages/requests/api.py", line 73, in get
    return request("get", url, params=params, **kwargs)
  File "/home/airflow/.local/lib/python3.7/site-packages/requests/api.py", line 59, in request
    return session.request(method=method, url=url, **kwargs)
  File "/home/airflow/.local/lib/python3.7/site-packages/requests/sessions.py", line 587, in request
    resp = self.send(prep, **send_kwargs)
  File "/home/airflow/.local/lib/python3.7/site-packages/requests/sessions.py", line 701, in send
    r = adapter.send(request, **kwargs)
  File "/home/airflow/.local/lib/python3.7/site-packages/requests/adapters.py", line 520, in send
    raise ConnectionError(e, request=request)
requests.exceptions.ConnectionError: HTTPSConnectionPool(host='api.example.com', port=443): Max retries exceeded with url: /data (Caused by NewConnectionError('<urllib3.connection.HTTPSConnection object at 0x7fa93a27b210>: Failed to establish a new connection: [Errno -3] Temporary failure in name resolution'))
[2025-02-19T06:38:20.501+0000] {taskinstance.py:1373} INFO - Marking task as UP_FOR_RETRY. dag_id=api_to_snowflake, task_id=fetch_api_data, execution_date=20250218T063804, start_date=20250219T063812, end_date=20250219T063820
[2025-02-19T06:38:20.516+0000] {standard_task_runner.py:109} ERROR - Failed to execute job 2 for task fetch_api_data (HTTPSConnectionPool(host='api.example.com', port=443): Max retries exceeded with url: /data (Caused by NewConnectionError('<urllib3.connection.HTTPSConnection object at 0x7fa93a27b210>: Failed to establish a new connection: [Errno -3] Temporary failure in name resolution')); 156)
[2025-02-19T06:38:20.541+0000] {local_task_job_runner.py:232} INFO - Task exited with return code 1
[2025-02-19T06:38:20.565+0000] {taskinstance.py:2674} INFO - 0 downstream tasks scheduled from follow-on schedule check
